<robot
  name="roborts">

  <link name="base_footprint"/>

  <joint name="base_joint" type="fixed">
    <parent link="base_footprint"/>
    <child link="base_link" />
    <origin xyz="0 0 0" rpy="0 0 0"/>
  </joint>

  <link
    name="base_link">
    <inertial>
      <origin
        xyz="0.0911703133114876 0.532603557688202 -0.0712304066002232"
        rpy="0 0 0" />
      <mass
        value="12.50345535509228" />
      <inertia
        ixx="0.0696144181432877"
        ixy="-4.10992920734967E-06"
        ixz="5.83569660872888E-05"
        iyy="0.0299049539551884"
        iyz="-0.00505054745740228"
        izz="0.084986264822875" />
    </inertial>
    <visual>
      <origin
        xyz="0 0 0"
        rpy="0 0 0" />
      <geometry>
        <mesh
          filename="package://roborts_gazebo/meshes/base_link.STL" />
      </geometry>
      <material
        name="">
        <color
          rgba="0.792156862745098 0.819607843137255 0.933333333333333 1" />
      </material>
    </visual>
    <collision>
      <origin
        xyz="0 0 0"
        rpy="0 0 0" />
      <geometry>
        <mesh
          filename="package://roborts_gazebo/meshes/base_link.STL" />
      </geometry>
    </collision>
  </link>
  <link
    name="Front_Right_Wheel">
    <inertial>
      <origin
        xyz="-0.023927 -4.9049E-06 -4.7297E-07"
        rpy="0 0 0" />
      <mass
        value="0.21911" />
      <inertia
        ixx="0.00087242"
        ixy="-2.3396E-08"
        ixz="2.3653E-07"
        iyy="0.00045739"
        iyz="-5.7565E-08"
        izz="0.00045797" />
    </inertial>
    <visual>
      <origin
        xyz="0 0 0"
        rpy="0 0 0" />
      <geometry>
        <mesh
          filename="package://roborts_gazebo/meshes/Front_Right_Wheel.STL" />
      </geometry>
      <material
        name="">
        <color
          rgba="0.79216 0.81961 0.93333 1" />
      </material>
    </visual>
    <collision>
      <origin
        xyz="0 0 0"
        rpy="0 0 0" />
      <geometry>
        <mesh
          filename="package://roborts_gazebo/meshes/Front_Right_Wheel.STL" />
      </geometry>
    </collision>
  </link>
  <joint
    name="Front_Right_Wheel_Joint"
    type="fixed">
    <origin
      xyz="-0.084088 0.020672 0.74645"
      rpy="1.5708 0 0" />
    <parent
      link="base_link" />
    <child
      link="Front_Right_Wheel" />
    <axis
      xyz="1 0 0" />
    <limit
      effort="0"
      velocity="0" />
  </joint>
  <link
    name="Front_Left_Wheel">
    <inertial>
      <origin
        xyz="0.024147 -1.0711E-05 5.6176E-05"
        rpy="0 0 0" />
      <mass
        value="0.21911" />
      <inertia
        ixx="0.00087242"
        ixy="9.7827E-09"
        ixz="2.3932E-07"
        iyy="0.00045756"
        iyz="8.8102E-08"
        izz="0.0004578" />
    </inertial>
    <visual>
      <origin
        xyz="0 0 0"
        rpy="0 0 0" />
      <geometry>
        <mesh
          filename="package://roborts_gazebo/meshes/Front_Left_Wheel.STL" />
      </geometry>
      <material
        name="">
        <color
          rgba="0.79216 0.81961 0.93333 1" />
      </material>
    </visual>
    <collision>
      <origin
        xyz="0 0 0"
        rpy="0 0 0" />
      <geometry>
        <mesh
          filename="package://roborts_gazebo/meshes/Front_Left_Wheel.STL" />
      </geometry>
    </collision>
  </link>
  <joint
    name="Front_Left_Wheel_Joint"
    type="fixed">
    <origin
      xyz="0.26361 0.020672 0.74645"
      rpy="1.5708 0 0" />
    <parent
      link="base_link" />
    <child
      link="Front_Left_Wheel" />
    <axis
      xyz="1 0 0" />
    <limit
      effort="0"
      velocity="0" />
  </joint>
  <link
    name="Rear_Right_Wheel">
    <inertial>
      <origin
        xyz="-0.023927 -4.8934E-06 -4.7019E-07"
        rpy="0 0 0" />
      <mass
        value="0.21911" />
      <inertia
        ixx="0.00087242"
        ixy="-2.3408E-08"
        ixz="2.3652E-07"
        iyy="0.00045739"
        iyz="-5.761E-08"
        izz="0.00045797" />
    </inertial>
    <visual>
      <origin
        xyz="0 0 0"
        rpy="0 0 0" />
      <geometry>
        <mesh
          filename="package://roborts_gazebo/meshes/Rear_Right_Wheel.STL" />
      </geometry>
      <material
        name="">
        <color
          rgba="0.79216 0.81961 0.93333 1" />
      </material>
    </visual>
    <collision>
      <origin
        xyz="0 0 0"
        rpy="0 0 0" />
      <geometry>
        <mesh
          filename="package://roborts_gazebo/meshes/Rear_Right_Wheel.STL" />
      </geometry>
    </collision>
  </link>
  <joint
    name="Rear_Right_Wheel_Joint"
    type="fixed">
    <origin
      xyz="-0.084088 0.020672 0.33145"
      rpy="1.5708 0 0" />
    <parent
      link="base_link" />
    <child
      link="Rear_Right_Wheel" />
    <axis
      xyz="1 0 0" />
    <limit
      effort="0"
      velocity="0" />
  </joint>
  <link
    name="Rear_Left_Wheel">
    <inertial>
      <origin
        xyz="0.024147 -1.074E-05 5.6187E-05"
        rpy="0 0 0" />
      <mass
        value="0.21911" />
      <inertia
        ixx="0.00087242"
        ixy="9.7549E-09"
        ixz="2.3931E-07"
        iyy="0.00045756"
        iyz="8.8211E-08"
        izz="0.0004578" />
    </inertial>
    <visual>
      <origin
        xyz="0 0 0"
        rpy="0 0 0" />
      <geometry>
        <mesh
          filename="package://roborts_gazebo/meshes/Rear_Left_Wheel.STL" />
      </geometry>
      <material
        name="">
        <color
          rgba="0.79216 0.81961 0.93333 1" />
      </material>
    </visual>
    <collision>
      <origin
        xyz="0 0 0"
        rpy="0 0 0" />
      <geometry>
        <mesh
          filename="package://roborts_gazebo/meshes/Rear_Left_Wheel.STL" />
      </geometry>
    </collision>
  </link>
  <joint
    name="Rear_Left_Wheel_Joint"
    type="fixed">
    <origin
      xyz="0.26361 0.020672 0.33145"
      rpy="1.5708 0 0" />
    <parent
      link="base_link" />
    <child
      link="Rear_Left_Wheel" />
    <axis
      xyz="1 0 0" />
    <limit
      effort="0"
      velocity="0" />
  </joint>
  <link
    name="Projector_Bottom">
    <inertial>
      <origin
        xyz="4.8668E-06 0.00071637 -0.016694"
        rpy="0 0 0" />
      <mass
        value="0.19516" />
      <inertia
        ixx="7.1489E-05"
        ixy="-1.1693E-08"
        ixz="-1.128E-08"
        iyy="7.2978E-05"
        iyz="-6.8136E-07"
        izz="0.00011961" />
    </inertial>
    <visual>
      <origin
        xyz="0 0 0"
        rpy="0 0 0" />
      <geometry>
        <mesh
          filename="package://roborts_gazebo/meshes/Projector_Bottom.STL" />
      </geometry>
      <material
        name="">
        <color
          rgba="0.79216 0.81961 0.93333 1" />
      </material>
    </visual>
    <collision>
      <origin
        xyz="0 0 0"
        rpy="0 0 0" />
      <geometry>
        <mesh
          filename="package://roborts_gazebo/meshes/Projector_Bottom.STL" />
      </geometry>
    </collision>
  </link>
  <joint
    name="Projector_Bottom_Joint"
    type="fixed">
    <origin
      xyz="0.090263 0.15807 0.54555"
      rpy="1.5708 0 0" />
    <parent
      link="base_link" />
    <child
      link="Projector_Bottom" />
    <axis
      xyz="0 0 1" />
  </joint>
  <link
    name="Projector_Middle">
    <inertial>
      <origin
        xyz="-0.0097345 -0.0020474 -0.11012"
        rpy="0 0 0" />
      <mass
        value="0.22467" />
      <inertia
        ixx="0.00062555"
        ixy="9.1288E-06"
        ixz="-0.00020804"
        iyy="0.00087911"
        iyz="3.4967E-05"
        izz="0.00037095" />
    </inertial>
    <visual>
      <origin
        xyz="0 0 0"
        rpy="0 0 0" />
      <geometry>
        <mesh
          filename="package://roborts_gazebo/meshes/Projector_Middle.STL" />
      </geometry>
      <material
        name="">
        <color
          rgba="0.79216 0.81961 0.93333 1" />
      </material>
    </visual>
    <collision>
      <origin
        xyz="0 0 0"
        rpy="0 0 0" />
      <geometry>
        <mesh
          filename="package://roborts_gazebo/meshes/Projector_Middle.STL" />
      </geometry>
    </collision>
  </link>
  <joint
    name="Projector_Middle_Joint"
    type="revolute">
    <origin
      xyz="0.090263 0.16907 0.54555"
      rpy="1.5708 0 0" />
    <parent
      link="base_link" />
    <child
      link="Projector_Middle" />
    <axis
      xyz="0 0 1" />
    <limit
      lower="-1.57"
      upper="1.57"
      effort="1000"
      velocity="100" />
  </joint>
  <link
    name="Projector_Top">
    <inertial>
      <origin
        xyz="-0.0032332 0.03966 -0.060086"
        rpy="0 0 0" />
      <mass
        value="0.31606" />
      <inertia
        ixx="0.0015216"
        ixy="-0.00011064"
        ixz="2.4346E-05"
        iyy="0.00029564"
        iyz="-0.0001663"
        izz="0.0014807" />
    </inertial>
    <visual>
      <origin
        xyz="0 0 0"
        rpy="0 0 0" />
      <geometry>
        <mesh
          filename="package://roborts_gazebo/meshes/Projector_Top.STL" />
      </geometry>
      <material
        name="">
        <color
          rgba="0.79216 0.81961 0.93333 1" />
      </material>
    </visual>
    <collision>
      <origin
        xyz="0 0 0"
        rpy="0 0 0" />
      <geometry>
        <mesh
          filename="package://roborts_gazebo/meshes/Projector_Top.STL" />
      </geometry>
    </collision>
  </link>
  <joint
    name="Projector_Top_Joint"
    type="revolute">
    <origin
      xyz="0.090263 0.26607 0.54555"
      rpy="1.5708 0 0" />
    <parent
      link="base_link" />
    <child
      link="Projector_Top" />
    <axis
      xyz="0 1 0" />
    <limit
      lower="-0.4"
      upper="0.4" 
      effort="1000"
      velocity="100" />
  </joint>
</robot>